Workbook

Sheet Base Cruz
A1: Cliente | B1: Razão Social | C1: AG | D1: Caixas Comodatadas | E1: Vol. Real Hl Trimestral | F1: Vol. Real Cx Trimestral | G1: Giro Trimestral | H1: Vol. Real Hl Mensal | I1: Vol. Real Cx Mensal | J1: Giro | K1: Tend. Giro | L1: Meta Unit. | M1: Item Comodato | N1: tipo | O1: Quantidade | P1: Valor Uni. | Q1: Valor Tot. | R1: Tipo Giro Trimestral | S1: Tipo Giro Mensal | T1: Nome Fantasia | U1: Setor | V1: GV | W1: Tipo de Vasilhame | X1: Comprou | Y1: Falta Comprar | Z1: Meta | AA1: Tendência | AF1: INICIO DO MÊS | AG1: HOJE | AH1: INICIO DO MÊS - HOJE
A2: 197 | B2: ACARAU CONVENIENCIA | C2: Cerveja 1/2 | D2: 6 | E2: 0.41 | F2: 6 | G2: 0.22 | H2: 0 | I2: 0 | J2: 0 | K2: 0 | L2: 1.5 | M2: 296156 | N2: GARRAFEIRA PLAST,23 GFA 300ML,AZUL | O2: 6 | P2: 29.77 | Q2: 178.62 | R2: Não OK | S2: Zero | T2: =VLOOKUP(Tabela2[[#This Row],[Cliente]],Setor!$C$2:$F$1606,4,0) -> ZE - ARMAZEM EXPRESS | U2: =VLOOKUP(Tabela2[[#This Row],[Cliente]],Setor!$C:$AU,45,0) -> 501 | V2: =_xlfn.XLOOKUP(Tabela2[[#This Row],[Setor]],AD:AD,AE:AE) -> Fredson | W2: =IF(Tabela2[[#This Row],[Meta Unit.]]=2,"SEISCENTOS","LITRINHO") -> LITRINHO | X2: =Tabela2[[#This Row],[Vol. Real Cx Mensal]] -> 0 | Y2: =(Tabela2[[#This Row],[Caixas Comodatadas]]*Tabela2[[#This Row],[Meta Unit.]])-Tabela2[[#This Row],[Comprou]] -> 9 | Z2: =IF(Tabela2[[#This Row],[Tipo de Vasilhame]] = "LITRINHO",1.5*Tabela2[[#This Row],[Caixas Comodatadas]],Tabela2[[#This Row],[Caixas Comodatadas]]*2) -> 9 | AA2: =IFERROR(IF(OR(FIND("OK", Tabela2[[#This Row],[Tipo Giro Mensal]]) > 0), IF(Tabela2[[#This Row],[Comprou]]/$AH$2*30 > Tabela2[[#This Row],[Meta]], "BATE", "ABAIXO"), "-"),"-") -> - | AF2: 46082 | AG2: =TODAY() -> 46111 | AH2: =AG2-AF2 -> 29
A3: 221 | B3: JOSE ZILMAR ARAUJO | C3: Cerveja 1/2 | D3: 5 | E3: 6.55 | F3: 95 | G3: 4.22 | H3: 1.17 | I3: 17 | J3: 2.27 | K3: 21.25 | L3: 1.5 | M3: 296156 | N3: GARRAFEIRA PLAST,23 GFA 300ML,AZUL | O3: 5 | P3: 29.77 | Q3: 148.85 | R3: OK | S3: OK | T3: =VLOOKUP(Tabela2[[#This Row],[Cliente]],Setor!$C$2:$F$1606,4,0) -> RANCHO DA ROCA | U3: =VLOOKUP(Tabela2[[#This Row],[Cliente]],Setor!$C:$AU,45,0) -> 102 | V3: =_xlfn.XLOOKUP(Tabela2[[#This Row],[Setor]],AD:AD,AE:AE) -> Fredson | W3: =IF(Tabela2[[#This Row],[Meta Unit.]]=2,"SEISCENTOS","LITRINHO") -> LITRINHO | X3: =Tabela2[[#This Row],[Vol. Real Cx Mensal]] -> 17 | Y3: =(Tabela2[[#This Row],[Caixas Comodatadas]]*Tabela2[[#This Row],[Meta Unit.]])-Tabela2[[#This Row],[Comprou]] -> -9.5 | Z3: =IF(Tabela2[[#This Row],[Tipo de Vasilhame]] = "LITRINHO",1.5*Tabela2[[#This Row],[Caixas Comodatadas]],Tabela2[[#This Row],[Caixas Comodatadas]]*2) -> 7.5 | AA3: =IFERROR(IF(OR(FIND("OK", Tabela2[[#This Row],[Tipo Giro Mensal]]) > 0), IF(Tabela2[[#This Row],[Comprou]]/$AH$2*30 > Tabela2[[#This Row],[Meta]], "BATE", "ABAIXO"), "-"),"-") -> BATE | AD3: SETORES | AE3: GV
A4: 271 | B4: JACINTA GUILHERME DE SOUSA SANTOS | C4: Cerveja 1/2 | D4: 2 | E4: 0.82 | F4: 12 | G4: 1.33 | H4: 0.27 | I4: 4 | J4: 1.33 | K4: 5 | L4: 1.5 | M4: 296156 | N4: GARRAFEIRA PLAST,23 GFA 300ML,AZUL | O4: 2 | P4: 29.77 | Q4: 59.54 | R4: OK | S4: OK | T4: =VLOOKUP(Tabela2[[#This Row],[Cliente]],Setor!$C$2:$F$1606,4,0) -> BAR DA JACINTA CORR | U4: =VLOOKUP(Tabela2[[#This Row],[Cliente]],Setor!$C:$AU,45,0) -> 104 | V4: =_xlfn.XLOOKUP(Tabela2[[#This Row],[Setor]],AD:AD,AE:AE) -> Fredson | W4: =IF(Tabela2[[#This Row],[Meta Unit.]]=2,"SEISCENTOS","LITRINHO") -> LITRINHO | X4: =Tabela2[[#This Row],[Vol. Real Cx Mensal]] -> 4 | Y4: =(Tabela2[[#This Row],[Caixas Comodatadas]]*Tabela2[[#This Row],[Meta Unit.]])-Tabela2[[#This Row],[Comprou]] -> -1 | Z4: =IF(Tabela2[[#This Row],[Tipo de Vasilhame]] = "LITRINHO",1.5*Tabela2[[#This Row],[Caixas Comodatadas]],Tabela2[[#This Row],[Caixas Comodatadas]]*2) -> 3 | AA4: =IFERROR(IF(OR(FIND("OK", Tabela2[[#This Row],[Tipo Giro Mensal]]) > 0), IF(Tabela2[[#This Row],[Comprou]]/$AH$2*30 > Tabela2[[#This Row],[Meta]], "BATE", "ABAIXO"), "-"),"-") -> BATE | AD4: 100 | AE4: Jaissa
A5: 320 | B5: FRANCISCO RICARDO ARAUJO | C5: Cerveja 1/2 | D5: 10 | E5: 11.52 | F5: 167 | G5: 3.71 | H5: 0 | I5: 0 | J5: 0 | K5: 0 | L5: 1.5 | M5: 296156 | N5: GARRAFEIRA PLAST,23 GFA 300ML,AZUL | O5: 10 | P5: 29.77 | Q5: 297.7 | R5: OK | S5: Zero Total | T5: =VLOOKUP(Tabela2[[#This Row],[Cliente]],Setor!$C$2:$F$1606,4,0) -> MERC RICARDO TIMBIR | U5: =VLOOKUP(Tabela2[[#This Row],[Cliente]],Setor!$C:$AU,45,0) -> 105 | V5: =_xlfn.XLOOKUP(Tabela2[[#This Row],[Setor]],AD:AD,AE:AE) -> Jaissa | W5: =IF(Tabela2[[#This Row],[Meta Unit.]]=2,"SEISCENTOS","LITRINHO") -> LITRINHO | X5: =Tabela2[[#This Row],[Vol. Real Cx Mensal]] -> 0 | Y5: =(Tabela2[[#This Row],[Caixas Comodatadas]]*Tabela2[[#This Row],[Meta Unit.]])-Tabela2[[#This Row],[Comprou]] -> 15 | Z5: =IF(Tabela2[[#This Row],[Tipo de Vasilhame]] = "LITRINHO",1.5*Tabela2[[#This Row],[Caixas Comodatadas]],Tabela2[[#This Row],[Caixas Comodatadas]]*2) -> 15 | AA5: =IFERROR(IF(OR(FIND("OK", Tabela2[[#This Row],[Tipo Giro Mensal]]) > 0), IF(Tabela2[[#This Row],[Comprou]]/$AH$2*30 > Tabela2[[#This Row],[Meta]], "BATE", "ABAIXO"), "-"),"-") -> - | AD5: 103 | AE5: Jaissa
A6: 345 | B6: MARIA ELIANE SILVEIRA | C6: Cerveja 1/2 | D6: 4 | E6: 5.38 | F6: 78 | G6: 4.33 | H6: 0.69 | I6: 10 | J6: 1.67 | K6: 12.5 | L6: 1.5 | M6: 296156 | N6: GARRAFEIRA PLAST,23 GFA 300ML,AZUL | O6: 4 | P6: 29.77 | Q6: 119.08 | R6: OK | S6: OK | T6: =VLOOKUP(Tabela2[[#This Row],[Cliente]],Setor!$C$2:$F$1606,4,0) -> BAR DO COXINHA CRUZ | U6: =VLOOKUP(Tabela2[[#This Row],[Cliente]],Setor!$C:$AU,45,0) -> 105 | V6: =_xlfn.XLOOKUP(Tabela2[[#This Row],[Setor]],AD:AD,AE:AE) -> Jaissa | W6: =IF(Tabela2[[#This Row],[Meta Unit.]]=2,"SEISCENTOS","LITRINHO") -> LITRINHO | X6: =Tabela2[[#This Row],[Vol. Real Cx Mensal]] -> 10 | Y6: =(Tabela2[[#This Row],[Caixas Comodatadas]]*Tabela2[[#This Row],[Meta Unit.]])-Tabela2[[#This Row],[Comprou]] -> -4 | Z6: =IF(Tabela2[[#This Row],[Tipo de Vasilhame]] = "LITRINHO",1.5*Tabela2[[#This Row],[Caixas Comodatadas]],Tabela2[[#This Row],[Caixas Comodatadas]]*2) -> 6 | AA6: =IFERROR(IF(OR(FIND("OK", Tabela2[[#This Row],[Tipo Giro Mensal]]) > 0), IF(Tabela2[[#This Row],[Comprou]]/$AH$2*30 > Tabela2[[#This Row],[Meta]], "BATE", "ABAIXO"), "-"),"-") -> BATE | AD6: 105 | AE6: Jaissa
A7: 388 | B7: FRANCISCO LEANDRO CRUZ ME | C7: Cerveja 1/1 | D7: 6 | E7: 0 | F7: 0 | G7: 0 | H7: 0.57 | I7: 4 | J7: 0.33 | K7: 5 | L7: 2 | M7: 103330 | N7: GARRAFEIRA PLAST,24 GFA 600ML,ANTARCTICA, | O7: 6 | P7: 43.86 | Q7: 263.16 | R7: Zero | S7: Não OK | T7: =VLOOKUP(Tabela2[[#This Row],[Cliente]],Setor!$C$2:$F$1606,4,0) -> SUPERMERCADO SKINAO | U7: =VLOOKUP(Tabela2[[#This Row],[Cliente]],Setor!$C:$AU,45,0) -> 501 | V7: =_xlfn.XLOOKUP(Tabela2[[#This Row],[Setor]],AD:AD,AE:AE) -> Fredson | W7: =IF(Tabela2[[#This Row],[Meta Unit.]]=2,"SEISCENTOS","LITRINHO") -> SEISCENTOS | X7: =Tabela2[[#This Row],[Vol. Real Cx Mensal]] -> 4 | Y7: =(Tabela2[[#This Row],[Caixas Comodatadas]]*Tabela2[[#This Row],[Meta Unit.]])-Tabela2[[#This Row],[Comprou]] -> 8 | Z7: =IF(Tabela2[[#This Row],[Tipo de Vasilhame]] = "LITRINHO",1.5*Tabela2[[#This Row],[Caixas Comodatadas]],Tabela2[[#This Row],[Caixas Comodatadas]]*2) -> 12 | AA7: =IFERROR(IF(OR(FIND("OK", Tabela2[[#This Row],[Tipo Giro Mensal]]) > 0), IF(Tabela2[[#This Row],[Comprou]]/$AH$2*30 > Tabela2[[#This Row],[Meta]], "BATE", "ABAIXO"), "-"),"-") -> ABAIXO | AD7: 106 | AE7: Jaissa
A8: 388 | B8: FRANCISCO LEANDRO CRUZ ME | C8: Cerveja 1/2 | D8: 50 | E8: 8.83 | F8: 128 | G8: 0.57 | H8: 1.03 | I8: 15 | J8: 0.2 | K8: 18.75 | L8: 1.5 | M8: 296156 | N8: GARRAFEIRA PLAST,23 GFA 300ML,AZUL | O8: 50 | P8: 29.77 | Q8: 1488.5 | R8: Não OK | S8: Não OK | T8: =VLOOKUP(Tabela2[[#This Row],[Cliente]],Setor!$C$2:$F$1606,4,0) -> SUPERMERCADO SKINAO | U8: =VLOOKUP(Tabela2[[#This Row],[Cliente]],Setor!$C:$AU,45,0) -> 501 | V8: =_xlfn.XLOOKUP(Tabela2[[#This Row],[Setor]],AD:AD,AE:AE) -> Fredson | W8: =IF(Tabela2[[#This Row],[Meta Unit.]]=2,"SEISCENTOS","LITRINHO") -> LITRINHO | X8: =Tabela2[[#This Row],[Vol. Real Cx Mensal]] -> 15 | Y8: =(Tabela2[[#This Row],[Caixas Comodatadas]]*Tabela2[[#This Row],[Meta Unit.]])-Tabela2[[#This Row],[Comprou]] -> 60 | Z8: =IF(Tabela2[[#This Row],[Tipo de Vasilhame]] = "LITRINHO",1.5*Tabela2[[#This Row],[Caixas Comodatadas]],Tabela2[[#This Row],[Caixas Comodatadas]]*2) -> 75 | AA8: =IFERROR(IF(OR(FIND("OK", Tabela2[[#This Row],[Tipo Giro Mensal]]) > 0), IF(Tabela2[[#This Row],[Comprou]]/$AH$2*30 > Tabela2[[#This Row],[Meta]], "BATE", "ABAIXO"), "-"),"-") -> ABAIXO | AD8: 500 | AE8: Jaissa
A9: 407 | B9: JOSE JONAS DOS SANTOS | C9: Cerveja 1/2 | D9: 30 | E9: 44.85 | F9: 650 | G9: 4.81 | H9: 0 | I9: 0 | J9: 0 | K9: 0 | L9: 1.5 | M9: 296156 | N9: GARRAFEIRA PLAST,23 GFA 300ML,AZUL | O9: 30 | P9: 29.77 | Q9: 893.1 | R9: OK | S9: Zero | T9: =VLOOKUP(Tabela2[[#This Row],[Cliente]],Setor!$C$2:$F$1606,4,0) -> JOSE JONAS CURRAL V | U9: =VLOOKUP(Tabela2[[#This Row],[Cliente]],Setor!$C:$AU,45,0) -> 501 | V9: =_xlfn.XLOOKUP(Tabela2[[#This Row],[Setor]],AD:AD,AE:AE) -> Fredson | W9: =IF(Tabela2[[#This Row],[Meta Unit.]]=2,"SEISCENTOS","LITRINHO") -> LITRINHO | X9: =Tabela2[[#This Row],[Vol. Real Cx Mensal]] -> 0 | Y9: =(Tabela2[[#This Row],[Caixas Comodatadas]]*Tabela2[[#This Row],[Meta Unit.]])-Tabela2[[#This Row],[Comprou]] -> 45 | Z9: =IF(Tabela2[[#This Row],[Tipo de Vasilhame]] = "LITRINHO",1.5*Tabela2[[#This Row],[Caixas Comodatadas]],Tabela2[[#This Row],[Caixas Comodatadas]]*2) -> 45 | AA9: =IFERROR(IF(OR(FIND("OK", Tabela2[[#This Row],[Tipo Giro Mensal]]) > 0), IF(Tabela2[[#This Row],[Comprou]]/$AH$2*30 > Tabela2[[#This Row],[Meta]], "BATE", "ABAIXO"), "-"),"-") -> - | AD9: 101 | AE9: Fredson
A10: 876 | B10: M EAMP | C10: Cerveja 1/1 | D10: 6 | E10: 22.17 | F10: 154 | G10: 4.28 | H10: 1.58 | I10: 11 | J10: 0.92 | K10: 13.75 | L10: 2 | M10: 30491 | N10: GARRAFEIRA PLAST,24 GFA 600ML,SKOL,C/1, | O10: 6 | P10: 43.86 | Q10: 263.16 | R10: OK | S10: Não OK | T10: =VLOOKUP(Tabela2[[#This Row],[Cliente]],Setor!$C$2:$F$1606,4,0) -> S5 - REST LUA CHEIA | U10: =VLOOKUP(Tabela2[[#This Row],[Cliente]],Setor!$C:$AU,45,0) -> 500 | V10: =_xlfn.XLOOKUP(Tabela2[[#This Row],[Setor]],AD:AD,AE:AE) -> Jaissa | W10: =IF(Tabela2[[#This Row],[Meta Unit.]]=2,"SEISCENTOS","LITRINHO") -> SEISCENTOS | X10: =Tabela2[[#This Row],[Vol. Real Cx Mensal]] -> 11 | Y10: =(Tabela2[[#This Row],[Caixas Comodatadas]]*Tabela2[[#This Row],[Meta Unit.]])-Tabela2[[#This Row],[Comprou]] -> 1 | Z10: =IF(Tabela2[[#This Row],[Tipo de Vasilhame]] = "LITRINHO",1.5*Tabela2[[#This Row],[Caixas Comodatadas]],Tabela2[[#This Row],[Caixas Comodatadas]]*2) -> 12 | AA10: =IFERROR(IF(OR(FIND("OK", Tabela2[[#This Row],[Tipo Giro Mensal]]) > 0), IF(Tabela2[[#This Row],[Comprou]]/$AH$2*30 > Tabela2[[#This Row],[Meta]], "BATE", "ABAIXO"), "-"),"-") -> ABAIXO | AD10: 102 | AE10: Fredson
A11: 2918 | B11: JOAO VICTOR DO NASCIMENTO BRANDAO | C11: Cerveja 1/2 | D11: 10 | E11: 6.55 | F11: 95 | G11: 2.11 | H11: 0.34 | I11: 5 | J11: 0.33 | K11: 6.25 | L11: 1.5 | M11: 296156 | N11: GARRAFEIRA PLAST,23 GFA 300ML,AZUL | O11: 10 | P11: 29.77 | Q11: 297.7 | R11: OK | S11: Não OK | T11: =VLOOKUP(Tabela2[[#This Row],[Cliente]],Setor!$C$2:$F$1606,4,0) -> CHINA ESPETO | U11: =VLOOKUP(Tabela2[[#This Row],[Cliente]],Setor!$C:$AU,45,0) -> 501 | V11: =_xlfn.XLOOKUP(Tabela2[[#This Row],[Setor]],AD:AD,AE:AE) -> Fredson | W11: =IF(Tabela2[[#This Row],[Meta Unit.]]=2,"SEISCENTOS","LITRINHO") -> LITRINHO | X11: =Tabela2[[#This Row],[Vol. Real Cx Mensal]] -> 5 | Y11: =(Tabela2[[#This Row],[Caixas Comodatadas]]*Tabela2[[#This Row],[Meta Unit.]])-Tabela2[[#This Row],[Comprou]] -> 10 | Z11: =IF(Tabela2[[#This Row],[Tipo de Vasilhame]] = "LITRINHO",1.5*Tabela2[[#This Row],[Caixas Comodatadas]],Tabela2[[#This Row],[Caixas Comodatadas]]*2) -> 15 | AA11: =IFERROR(IF(OR(FIND("OK", Tabela2[[#This Row],[Tipo Giro Mensal]]) > 0), IF(Tabela2[[#This Row],[Comprou]]/$AH$2*30 > Tabela2[[#This Row],[Meta]], "BATE", "ABAIXO"), "-"),"-") -> ABAIXO | AD11: 104 | AE11: Fredson
A12: 3105 | B12: MANOEL RODRIGO SILVA ROCHA | C12: Cerveja 1/1 | D12: 2 | E12: 3.88 | F12: 27 | G12: 2.25 | H12: 0.28 | I12: 2 | J12: 0.5 | K12: 2.5 | L12: 2 | M12: 30491 | N12: GARRAFEIRA PLAST,24 GFA 600ML,SKOL,C/1, | O12: 2 | P12: 43.86 | Q12: 87.72 | R12: OK | S12: Não OK | T12: =VLOOKUP(Tabela2[[#This Row],[Cliente]],Setor!$C$2:$F$1606,4,0) -> BARRACA POR DO SOL | U12: =VLOOKUP(Tabela2[[#This Row],[Cliente]],Setor!$C:$AU,45,0) -> 104 | V12: =_xlfn.XLOOKUP(Tabela2[[#This Row],[Setor]],AD:AD,AE:AE) -> Fredson | W12: =IF(Tabela2[[#This Row],[Meta Unit.]]=2,"SEISCENTOS","LITRINHO") -> SEISCENTOS | X12: =Tabela2[[#This Row],[Vol. Real Cx Mensal]] -> 2 | Y12: =(Tabela2[[#This Row],[Caixas Comodatadas]]*Tabela2[[#This Row],[Meta Unit.]])-Tabela2[[#This Row],[Comprou]] -> 2 | Z12: =IF(Tabela2[[#This Row],[Tipo de Vasilhame]] = "LITRINHO",1.5*Tabela2[[#This Row],[Caixas Comodatadas]],Tabela2[[#This Row],[Caixas Comodatadas]]*2) -> 4 | AA12: =IFERROR(IF(OR(FIND("OK", Tabela2[[#This Row],[Tipo Giro Mensal]]) > 0), IF(Tabela2[[#This Row],[Comprou]]/$AH$2*30 > Tabela2[[#This Row],[Meta]], "BATE", "ABAIXO"), "-"),"-") -> ABAIXO | AD12: 501 | AE12: Fredson
A13: 3877 | B13: LE CHARME JERICOACOARA LTDA | C13: Cerveja 1/1 | D13: 20 | E13: 4.46 | F13: 31 | G13: 0.26 | H13: 0.72 | I13: 5 | J13: 0.13 | K13: 6.25 | L13: 2 | M13: 899599 | N13: GARRAFEIRA PLAST,24 GFA 600ML,,,, | O13: 20 | P13: 20 | Q13: 400 | R13: Não OK | S13: Não OK | T13: =VLOOKUP(Tabela2[[#This Row],[Cliente]],Setor!$C$2:$F$1606,4,0) -> LE CHARME JERICOACOA | U13: =VLOOKUP(Tabela2[[#This Row],[Cliente]],Setor!$C:$AU,45,0) -> 106 | V13: =_xlfn.XLOOKUP(Tabela2[[#This Row],[Setor]],AD:AD,AE:AE) -> Jaissa | W13: =IF(Tabela2[[#This Row],[Meta Unit.]]=2,"SEISCENTOS","LITRINHO") -> SEISCENTOS | X13: =Tabela2[[#This Row],[Vol. Real Cx Mensal]] -> 5 | Y13: =(Tabela2[[#This Row],[Caixas Comodatadas]]*Tabela2[[#This Row],[Meta Unit.]])-Tabela2[[#This Row],[Comprou]] -> 35 | Z13: =IF(Tabela2[[#This Row],[Tipo de Vasilhame]] = "LITRINHO",1.5*Tabela2[[#This Row],[Caixas Comodatadas]],Tabela2[[#This Row],[Caixas Comodatadas]]*2) -> 40 | AA13: =IFERROR(IF(OR(FIND("OK", Tabela2[[#This Row],[Tipo Giro Mensal]]) > 0), IF(Tabela2[[#This Row],[Comprou]]/$AH$2*30 > Tabela2[[#This Row],[Meta]], "BATE", "ABAIXO"), "-"),"-") -> ABAIXO
A14: 3891 | B14: IERY MARIA ARAUJO OSTERNO CAVALCANTE | C14: Cerveja 1/1 | D14: 32 | E14: 1.15 | F14: 8 | G14: 0.04 | H14: 0.72 | I14: 5 | J14: 0.08 | K14: 6.25 | L14: 2 | M14: 899599 | N14: GARRAFEIRA PLAST,24 GFA 600ML,,,, | O14: 32 | P14: 20 | Q14: 640 | R14: Não OK | S14: Não OK | T14: =VLOOKUP(Tabela2[[#This Row],[Cliente]],Setor!$C$2:$F$1606,4,0) -> CANDIEIRO BAR E REST | U14: =VLOOKUP(Tabela2[[#This Row],[Cliente]],Setor!$C:$AU,45,0) -> 102 | V14: =_xlfn.XLOOKUP(Tabela2[[#This Row],[Setor]],AD:AD,AE:AE) -> Fredson | W14: =IF(Tabela2[[#This Row],[Meta Unit.]]=2,"SEISCENTOS","LITRINHO") -> SEISCENTOS | X14: =Tabela2[[#This Row],[Vol. Real Cx Mensal]] -> 5 | Y14: =(Tabela2[[#This Row],[Caixas Comodatadas]]*Tabela2[[#This Row],[Meta Unit.]])-Tabela2[[#This Row],[Comprou]] -> 59 | Z14: =IF(Tabela2[[#This Row],[Tipo de Vasilhame]] = "LITRINHO",1.5*Tabela2[[#This Row],[Caixas Comodatadas]],Tabela2[[#This Row],[Caixas Comodatadas]]*2) -> 64 | AA14: =IFERROR(IF(OR(FIND("OK", Tabela2[[#This Row],[Tipo Giro Mensal]]) > 0), IF(Tabela2[[#This Row],[Comprou]]/$AH$2*30 > Tabela2[[#This Row],[Meta]], "BATE", "ABAIXO"), "-"),"-") -> ABAIXO
T15: =VLOOKUP(Tabela2[[#This Row],[Cliente]],Setor!$C$2:$F$1606,4,0) -> #N/A | U15: =VLOOKUP(Tabela2[[#This Row],[Cliente]],Setor!$C:$AU,45,0) -> #N/A | V15: =_xlfn.XLOOKUP(Tabela2[[#This Row],[Setor]],AD:AD,AE:AE) -> #N/A | W15: =IF(Tabela2[[#This Row],[Meta Unit.]]=2,"SEISCENTOS","LITRINHO") -> LITRINHO | X15: =Tabela2[[#This Row],[Vol. Real Cx Mensal]] -> 0 | Y15: =(Tabela2[[#This Row],[Caixas Comodatadas]]*Tabela2[[#This Row],[Meta Unit.]])-Tabela2[[#This Row],[Comprou]] -> 0 | Z15: =IF(Tabela2[[#This Row],[Tipo de Vasilhame]] = "LITRINHO",1.5*Tabela2[[#This Row],[Caixas Comodatadas]],Tabela2[[#This Row],[Caixas Comodatadas]]*2) -> 0 | AA15: =IFERROR(IF(OR(FIND("OK", Tabela2[[#This Row],[Tipo Giro Mensal]]) > 0), IF(Tabela2[[#This Row],[Comprou]]/$AH$2*30 > Tabela2[[#This Row],[Meta]], "BATE", "ABAIXO"), "-"),"-") -> -
T16: =VLOOKUP(Tabela2[[#This Row],[Cliente]],Setor!$C$2:$F$1606,4,0) -> #N/A | U16: =VLOOKUP(Tabela2[[#This Row],[Cliente]],Setor!$C:$AU,45,0) -> #N/A | V16: =_xlfn.XLOOKUP(Tabela2[[#This Row],[Setor]],AD:AD,AE:AE) -> #N/A | W16: =IF(Tabela2[[#This Row],[Meta Unit.]]=2,"SEISCENTOS","LITRINHO") -> LITRINHO | X16: =Tabela2[[#This Row],[Vol. Real Cx Mensal]] -> 0 | Y16: =(Tabela2[[#This Row],[Caixas Comodatadas]]*Tabela2[[#This Row],[Meta Unit.]])-Tabela2[[#This Row],[Comprou]] -> 0 | Z16: =IF(Tabela2[[#This Row],[Tipo de Vasilhame]] = "LITRINHO",1.5*Tabela2[[#This Row],[Caixas Comodatadas]],Tabela2[[#This Row],[Caixas Comodatadas]]*2) -> 0 | AA16: =IFERROR(IF(OR(FIND("OK", Tabela2[[#This Row],[Tipo Giro Mensal]]) > 0), IF(Tabela2[[#This Row],[Comprou]]/$AH$2*30 > Tabela2[[#This Row],[Meta]], "BATE", "ABAIXO"), "-"),"-") -> -
R32: =9/183 -> 0.049180328

Sheet Setor
A1: Empresa | B1: Filial | C1: Cód PDV | D1: Documento | E1: Situação na RF | F1: Nome Fantasia | G1: Razão Social | H1: Endereço | I1: Complemento | J1: Bairro | K1: Cidade | L1: UF | M1: CEP | N1: Telefone(s) | O1: Categoria | P1: Cód Rede | Q1: Nome Rede | R1: Classe Risco Atual | S1: Pontuação Score | T1: Modelo Score | U1: Segmento Score | V1: Limite de Crédito | W1: Limite de Crédito Usado | X1: Limite de Crédito Disponível | Y1: Prazo Atual | Z1: Prazo Máximo Matriz | AA1: Maior Prazo por Título | AB1: Atraso Médio | AC1: Perc Pgto em Atraso | AD1: Possui Comodato | AE1: Situação Documentação | AF1: Data de Cadastro | AG1: Data da Última Compra | AH1: Compra Média | AI1: Maior Compra | AJ1: Acumulado de Vendas | AK1: Títulos Pendentes | AL1: Títulos à Vencer | AM1: Perc CR à Vencer (M-1) | AN1: Data de Envio Serasa | AO1: Data de Retorno Serasa | AP1: Cód EG | AQ1: Cliente em Inativação | AR1: Motivo Lista de Restrições | AS1: Tipo de Pessoa | AT1: Status do PDV | AU1: Setor VDE | AV1: Área VDE | AW1: GV VDE | AX1: Data Início da Visita VDE | AY1: Dia de Visita do VDE | AZ1: Data da Prox Visita VDE | BA1: Perc Positivação VDE(Mês) | BB1: Perc Positivação VDE(TRI) | BC1: Perc GPS VDE(Mês) | BD1: Setor VDI | BE1: Área VDI | BF1: GV VDI | BG1: Data Início da Visita VDI | BH1: Dia de Visita do VDI | BI1: Data da Prox Visita VDI | BJ1: Perc Positivação VDI(Mês) | BK1: Perc Positivação VDI(TRI) | BL1: Perc Contatos VDI(Mês) | BM1: Prazo Médio Ponderado à Prazo (M-1) | BN1: Prazo Médio Ponderado (M-1) | BO1: Faturamento à Prazo (M-1) | BP1: Faturamento DH (M-1) | BQ1: Faturamento Total (M-1) | BR1: CR a Vencer (M-1) | BS1: Prazo Médio Ponderado à Prazo (Mês) | BT1: Prazo Médio Ponderado (Mês) | BU1: Faturamento à Prazo (Mês) | BV1: Faturamento DH (Mês) | BW1: Faturamento Total (Mês) | BX1: CR a Vencer (Mês) | BY1: Perc CR a Vencer (Mês) | BZ1: Perc Atraso(6 meses) | CA1: Maior Atraso(6 meses) | CB1: Média Faturamento(3 meses) | CC1: Segmento NGE
A2: 345 | B2: 2 | C2: 1 | D2: 906.489.003-04 | F2: AGUA NA BOCA | G2: ELAINE CRISTINA RIOS FONTELES | H2: R R GUIDO OSTERNUO SN | J2: CENTRO | K2: MARCO | L2: CE | M2: 62.560-000 | N2: 88 99959-0105 | O2: ARMAZEM/MERCEARIA | P2: 0 | R2: 6 | S2: 38 | V2: 0 | W2: 0 | X2: 0 | Y2: 0 | Z2: 0 | AA2: 0 | AB2: 0 | AC2: 0 | AD2: Nao | AE2: Nao | AF2: 45518 | AG2: 46011 | AH2: 1112.78 | AI2: 1622.79 | AJ2: 5563.92 | AK2: 0 | AL2: 0 | AM2: 0 | AQ2: N | AS2: Fisica | AT2: Ativo | AU2: 102 | AV2: 10 | AW2: 1 | AX2: 45999 | AY2: SEG/ | AZ2: 46027 | BA2: 0 | BB2: 0 | BC2: 0 | BD2: 700 | BE2: 70 | BF2: 9 | BG2: 45536 | BH2: DOM/ | BI2: 46026 | BJ2: 0 | BK2: 0 | BL2: 0 | BM2: 0 | BN2: 0 | BO2: 0 | BP2: 3932.24 | BQ2: 3932.24 | BR2: 0 | BS2: 0 | BT2: 0 | BU2: 0 | BV2: 803.06 | BW2: 803.06 | BX2: 0 | BY2: 0 | BZ2: 0 | CA2: 0 | CB2: 1868.43 | CC2: TRAD
A3: 345 | B3: 2 | C3: 3 | D3: 21.261.228/0001-05 | F3: DEP RAIMUNDO MONTE | G3: TRES Y COMERCIAL DE ALIMENTOS | H3: R R GOVERNADOR RAUL BARBOSA 553 55553 | J3: CENTRO | K3: MARCO | L3: CE | M3: 62.560-000 | N3: 88 3664-1550 | O3: DEPOSITO DE BEBIDAS | P3: 0 | R3: 3 | S3: 88 | V3: 14700 | W3: 0 | X3: 14700 | Y3: 7 | Z3: 0 | AA3: 0 | AB3: 0 | AC3: 0 | AD3: Nao | AE3: Nao | AF3: 45518 | AG3: 46020 | AH3: 9902 | AI3: 21446 | AJ3: 128726 | AK3: 0 | AL3: 0 | AM3: 0 | AQ3: N | AS3: Juridica | AT3: Ativo | AU3: 501 | AV3: 10 | AW3: 1 | AX3: 45947 | AY3: SEX/ | AZ3: 46024 | BA3: 0 | BB3: 0 | BC3: 0 | BD3: 700 | BE3: 70 | BF3: 9 | BG3: 45536 | BH3: DOM/ | BI3: 46026 | BJ3: 0 | BK3: 0 | BL3: 0 | BM3: 0 | BN3: 0 | BO3: 0 | BP3: 37472.35 | BQ3: 37472.35 | BR3: 0 | BS3: 0 | BT3: 0 | BU3: 0 | BV3: 66554.5 | BW3: 66554.5 | BX3: 0 | BY3: 0 | BZ3: 0 | CA3: 0 | CB3: 34231.88 | CC3: SUB
A4: 345 | B4: 2 | C4: 4 | D4: 680.078.413-34 | F4: REST DA ELENITA TRI | G4: MARIA ELENITA LEITE | H4: RUA AV TRIANGULO DO MARCO 10 | J4: TRIANGULO DO MARCO | K4: MARCO | L4: CE | M4: 62.560-000 | N4: 88 3664-4053 | O4: REST./PIZZARIA/CHURR | P4: 0 | R4: 6 | S4: 36 | V4: 0 | W4: 0 | X4: 0 | Y4: 0 | Z4: 0 | AA4: 0 | AB4: 0 | AC4: 0 | AD4: Nao | AE4: Nao | AF4: 45518 | AG4: 46020 | AH4: 768.19 | AI4: 1269.28 | AJ4: 9986.55 | AK4: 0 | AL4: 0 | AM4: 0 | AQ4: N | AS4: Fisica | AT4: Ativo | AU4: 102 | AV4: 10 | AW4: 1 | AX4: 45815 | AY4: SAB/ | AZ4: 46025 | BA4: 0 | BB4: 0 | BC4: 0 | BD4: 700 | BE4: 70 | BF4: 9 | BG4: 45536 | BH4: DOM/ | BI4: 46026 | BJ4: 0 | BK4: 0 | BL4: 0 | BM4: 0 | BN4: 0 | BO4: 0 | BP4: 3441.49 | BQ4: 3441.49 | BR4: 0 | BS4: 0 | BT4: 0 | BU4: 0 | BV4: 3654.2 | BW4: 3654.2 | BX4: 0 | BY4: 0 | BZ4: 0 | CA4: 0 | CB4: 3049.15 | CC4: Rota
A5: 345 | B5: 2 | C5: 5 | D5: 547.792.353-91 | F5: BAR DO 100 MARCO | G5: JOAO VALNEY SILVA | H5: RUA R JOSE MARIA FARIAS 720 | J5: CENTRO | K5: MARCO | L5: CE | M5: 62.560-000 | N5: 88 99600-2082 | O5: BAR/BARZINHO | P5: 0 | R5: 6 | S5: 36 | V5: 0 | W5: 0 | X5: 0 | Y5: 0 | Z5: 0 | AA5: 0 | AB5: 0 | AC5: 0 | AD5: Nao | AE5: Nao | AF5: 45518 | AG5: 46018 | AH5: 515.09 | AI5: 869.76 | AJ5: 5666.02 | AK5: 0 | AL5: 0 | AM5: 0 | AQ5: N | AS5: Fisica | AT5: Ativo | AU5: 102 | AV5: 10 | AW5: 1 | AX5: 45847 | AY5: QUA/ | AZ5: 46022 | BA5: 0 | BB5: 0 | BC5: 0 | BD5: 700 | BE5: 70 | BF5: 9 | BG5: 45536 | BH5: DOM/ | BI5: 46026 | BJ5: 0 | BK5: 0 | BL5: 0 | BM5: 0 | BN5: 0 | BO5: 0 | BP5: 2066.7 | BQ5: 2066.7 | BR5: 0 | BS5: 0 | BT5: 0 | BU5: 0 | BV5: 1513.88 | BW5: 1513.88 | BX5: 0 | BY5: 0 | BZ5: 0 | CA5: 0 | CB5: 2068 | CC5: Rota
A6: 345 | B6: 2 | C6: 7 | D6: 923.862.373-20 | F6: MERC DO PAULO MARCO | G6: PAULO CESAR SOUZA | H6: RUA R VIRGILIO TAVORA 1713 | J6: ALEMAES | K6: MARCO | L6: CE | M6: 62.560-000 | N6: 88 99915-7756 | O6: ARMAZEM/MERCEARIA | P6: 0 | R6: 6 | S6: 41 | V6: 0 | W6: 0 | X6: 0 | Y6: 0 | Z6: 0 | AA6: 0 | AB6: 0 | AC6: 0 | AD6: Nao | AE6: Nao | AF6: 45518 | AG6: 46021 | AH6: 2542.74 | AI6: 9173.85 | AJ6: 35598.46 | AK6: 0 | AL6: 0 | AM6: 0 | AQ6: N | AS6: Fisica | AT6: Ativo | AU6: 102 | AV6: 10 | AW6: 1 | AX6: 45847 | AY6: QUA/ | AZ6: 46022 | BA6: 0 | BB6: 0 | BC6: 0 | BD6: 700 | BE6: 70 | BF6: 9 | BG6: 45536 | BH6: DOM/ | BI6: 46026 | BJ6: 0 | BK6: 0 | BL6: 0 | BM6: 0 | BN6: 0 | BO6: 0 | BP6: 8278.89 | BQ6: 8278.89 | BR6: 0 | BS6: 0 | BT6: 0 | BU6: 0 | BV6: 15164.36 | BW6: 15814.36 | BX6: 0 | BY6: 0 | BZ6: 0 | CA6: 0 | CB6: 14196.53 | CC6: TRAD
A7: 345 | B7: 2 | C7: 9 | D7: 048.352.613-48 | F7: CHUR MANOEL FRANKLIN | G7: JONAS FRANKLIM SILVA MELO | H7: EST EST TRIANGULO DE MARCO SN | J7: TRIANGULO DO MARCO | K7: MARCO | L7: CE | M7: 62.560-000 | N7: 88 3664-4009 | O7: BAR/BARZINHO | P7: 0 | R7: 6 | S7: 36 | V7: 0 | W7: 0 | X7: 0 | Y7: 0 | Z7: 0 | AA7: 0 | AB7: 0 | AC7: 0 | AD7: Nao | AE7: Nao | AF7: 45518 | AG7: 46019 | AH7: 205.74 | AI7: 390.17 | AJ7: 1851.69 | AK7: 0 | AL7: 0 | AM7: 0 | AQ7: N | AS7: Fisica | AT7: Ativo | AU7: 102 | AV7: 10 | AW7: 1 | AX7: 45966 | AY7: QUA/ | AZ7: 46022 | BA7: 0 | BB7: 0 | BC7: 0 | BD7: 700 | BE7: 70 | BF7: 9 | BG7: 45536 | BH7: DOM/ | BI7: 46026 | BJ7: 0 | BK7: 0 | BL7: 0 | BM7: 0 | BN7: 0 | BO7: 0 | BP7: 800.58 | BQ7: 800.58 | BR7: 0 | BS7: 0 | BT7: 0 | BU7: 0 | BV7: 763.67 | BW7: 763.67 | BX7: 0 | BY7: 0 | BZ7: 0 | CA7: 0 | CB7: 508.55 | CC7: Rota
A8: 345 | B8: 2 | C8: 12 | D8: 027.816.953-86 | F8: S5 - DEP SAO FRANCIS | G8: JOSE GLEISON ALVES | H8: R R PADRE APOLIANO SN | J8: ALEMAES | K8: MARCO | L8: CE | M8: 62.560-000 | N8: 08 89634-2862 | O8: BAR/BARZINHO | P8: 0 | R8: 6 | S8: 37 | V8: 0 | W8: 0 | X8: 0 | Y8: 0 | Z8: 0 | AA8: 0 | AB8: 0 | AC8: 0 | AD8: Nao | AE8: Nao | AF8: 45518 | AG8: 46020 | AH8: 4458.68 | AI8: 8936.87 | AJ8: 49045.51 | AK8: 0 | AL8: 0 | AM8: 0 | AQ8: N | AS8: Fisica | AT8: Ativo | AU8: 102 | AV8: 10 | AW8: 1 | AX8: 45843 | AY8: SAB/ | AZ8: 46025 | BA8: 0 | BB8: 0 | BC8: 0 | BD8: 700 | BE8: 70 | BF8: 9 | BG8: 45536 | BH8: DOM/ | BI8: 46026 | BJ8: 0 | BK8: 0 | BL8: 0 | BM8: 0 | BN8: 0 | BO8: 0 | BP8: 19076.56 | BQ8: 19076.56 | BR8: 0 | BS8: 0 | BT8: 0 | BU8: 0 | BV8: 21277.89 | BW8: 21277.89 | BX8: 0 | BY8: 0 | BZ8: 0 | CA8: 0 | CB8: 12789.82 | CC8: SUB
A9: 345 | B9: 2 | C9: 20 | D9: 907.050.333-68 | F9: MARCOS ANDRE | G9: MARCOS ANDRE GOMES | H9: R R FRANCISCO TEoFILO DA ROCHA SN | J9: ALEMAES | K9: MARCO | L9: CE | M9: 62.560-000 | N9: 88 99916-7948 | O9: ARMAZEM/MERCEARIA | P9: 0 | R9: 6 | S9: 39 | V9: 0 | W9: 0 | X9: 0 | Y9: 0 | Z9: 0 | AA9: 0 | AB9: 0 | AC9: 0 | AD9: Nao | AE9: Nao | AF9: 45518 | AG9: 46002 | AH9: 337.21 | AI9: 399.57 | AJ9: 674.42 | AK9: 0 | AL9: 0 | AM9: 0 | AQ9: N | AS9: Fisica | AT9: Ativo | AU9: 102 | AV9: 10 | AW9: 1 | AX9: 45847 | AY9: QUA/ | AZ9: 46022 | BA9: 0 | BB9: 0 | BC9: 0 | BD9: 700 | BE9: 70 | BF9: 9 | BG9: 45536 | BH9: DOM/ | BI9: 46026 | BJ9: 0 | BK9: 0 | BL9: 0 | BM9: 0 | BN9: 0 | BO9: 0 | BP9: 274.85 | BQ9: 274.85 | BR9: 0 | BS9: 0 | BT9: 0 | BU9: 0 | BV9: 399.57 | BW9: 399.57 | BX9: 0 | BY9: 0 | BZ9: 0 | CA9: 0 | CB9: 536.82 | CC9: TRAD
A10: 345 | B10: 2 | C10: 21 | D10: 14.420.595/0001-49 | F10: LANCH D GUSTE 99 | G10: CLAUDIA CRISTINA SILVA SILVEIRA ME. | H10: RUA R PADRE APOLIANO 357 | J10: CENTRO | K10: MARCO | L10: CE | M10: 62.560-000 | N10: 88 99915-2535 | O10: LANCHONETE/PASTELARI | P10: 0 | R10: 6 | S10: 40 | V10: 0 | W10: 0 | X10: 0 | Y10: 0 | Z10: 0 | AA10: 0 | AB10: 0 | AC10: 0 | AD10: Nao | AE10: Nao | AF10: 45518 | AG10: 46014 | AH10: 204.81 | AI10: 279.24 | AJ10: 1024.09 | AK10: 0 | AL10: 0 | AM10: 0 | AQ10: N | AS10: Juridica | AT10: Ativo | AU10: 102 | AV10: 10 | AW10: 1 | AX10: 45810 | AY10: SEG/ | AZ10: 46027 | BA10: 0 | BB10: 0 | BC10: 0 | BD10: 700 | BE10: 70 | BF10: 9 | BG10: 45536 | BH10: DOM/ | BI10: 46026 | BJ10: 0 | BK10: 0 | BL10: 0 | BM10: 0 | BN10: 0 | BO10: 0 | BP10: 188.15 | BQ10: 188.15 | BR10: 0 | BS10: 0 | BT10: 0 | BU10: 0 | BV10: 477.84 | BW10: 477.84 | BX10: 0 | BY10: 0 | BZ10: 0 | CA10: 0 | CB10: 182.08 | CC10: Rota
A11: 345 | B11: 2 | C11: 23 | D11: 907.205.123-87 | F11: MARIA ELIDENE | G11: MARIA ELIDENE DE SOUZA | H11: R R TRIANGULO DO MARCO SN | J11: TRIANGULO DO MARCO | K11: MARCO | L11: CE | M11: 62.560-000 | N11: 88 99964-1443 | O11: MINIMERCADO | P11: 0 | R11: 6 | S11: 41 | V11: 0 | W11: 0 | X11: 0 | Y11: 0 | Z11: 0 | AA11: 0 | AB11: 0 | AC11: 0 | AD11: Nao | AE11: Nao | AF11: 45518 | AG11: 46020 | AH11: 129.67 | AI11: 217.83 | AJ11: 1296.79 | AK11: 0 | AL11: 0 | AM11: 0 | AQ11: N | AS11: Fisica | AT11: Ativo | AU11: 102 | AV11: 10 | AW11: 1 | AX11: 45815 | AY11: SAB/ | AZ11: 46025 | BA11: 0 | BB11: 0 | BC11: 0 | BD11: 700 | BE11: 70 | BF11: 9 | BG11: 45536 | BH11: DOM/ | BI11: 46026 | BJ11: 0 | BK11: 0 | BL11: 0 | BM11: 0 | BN11: 0 | BO11: 0 | BP11: 229.2 | BQ11: 229.2 | BR11: 0 | BS11: 0 | BT11: 0 | BU11: 0 | BV11: 743.81 | BW11: 743.81 | BX11: 0 | BY11: 0 | BZ11: 0 | CA11: 0 | CB11: 302.65 | CC11: Rota
A12: 345 | B12: 2 | C12: 27 | D12: 682.119.703-25 | F12: MERC ROGENIO SANTA | G12: JOSE ROGENIO DE FREITAS | H12: VIL R SANTA ROSA 144 | J12: SANTA ROSA | K12: MARCO | L12: CE | M12: 62.560-000 | N12: 88 99640-1663 | O12: ARMAZEM/MERCEARIA | P12: 0 | R12: 6 | S12: 41 | V12: 0 | W12: 0 | X12: 0 | Y12: 0 | Z12: 0 | AA12: 0 | AB12: 0 | AC12: 0 | AD12: Nao | AE12: Nao | AF12: 45518 | AG12: 46021 | AH12: 1165.82 | AI12: 2855.54 | AJ12: 10492.45 | AK12: 0 | AL12: 0 | AM12: 0 | AQ12: N | AS12: Fisica | AT12: Ativo | AU12: 102 | AV12: 10 | AW12: 1 | AX12: 45537 | AY12: SEG/ | AZ12: 46027 | BA12: 0 | BB12: 0 | BC12: 0 | BD12: 700 | BE12: 70 | BF12: 9 | BG12: 45536 | BH12: DOM/ | BI12: 46026 | BJ12: 0 | BK12: 0 | BL12: 0 | BM12: 0 | BN12: 0 | BO12: 0 | BP12: 1060.81 | BQ12: 1060.81 | BR12: 0 | BS12: 0 | BT12: 0 | BU12: 0 | BV12: 7370.28 | BW12: 7370.28 | BX12: 0 | BY12: 0 | BZ12: 0 | CA12: 0 | CB12: 3101.34 | CC12: TRAD
A13: 345 | B13: 2 | C13: 28 | D13: 645.481.123-91 | F13: MERC SANDRO | G13: SANDRO JOVINO FREITAS | H13: VIL DT BOM JESUS I 10 | J13: TRIANGULO DO MARCO | K13: MARCO | L13: CE | M13: 62.560-000 | N13: 66 0064-4003 | O13: ARMAZEM/MERCEARIA | P13: 0 | R13: 6 | S13: 41 | V13: 0 | W13: 0 | X13: 0 | Y13: 0 | Z13: 0 | AA13: 0 | AB13: 0 | AC13: 0 | AD13: Nao | AE13: Nao | AF13: 45518 | AG13: 46020 | AH13: 1537.44 | AI13: 3156.79 | AJ13: 13837.03 | AK13: 0 | AL13: 0 | AM13: 0 | AQ13: N | AS13: Fisica | AT13: Ativo | AU13: 102 | AV13: 10 | AW13: 1 | AX13: 45815 | AY13: SAB/ | AZ13: 46025 | BA13: 0 | BB13: 0 | BC13: 0 | BD13: 700 | BE13: 70 | BF13: 9 | BG13: 45536 | BH13: DOM/ | BI13: 46026 | BJ13: 0 | BK13: 0 | BL13: 0 | BM13: 0 | BN13: 0 | BO13: 0 | BP13: 3446.97 | BQ13: 3446.97 | BR13: 0 | BS13: 0 | BT13: 0 | BU13: 0 | BV13: 7834.51 | BW13: 7834.51 | BX13: 0 | BY13: 0 | BZ13: 0 | CA13: 0 | CB13: 2804.25 | CC13: TRAD
... A19: 345 | B19: 2 | C19: 57 | D19: 007.628.153-10 | F19: REST ROTA DOS SABORE | G19: FRANCISCO ERONDI ARAUJO | H19: R TRIANGULO DO MARCO SN | J19: TRIANGULO DO MARCO | K19: MARCO | L19: CE | M19: 62.560-000 | N19: 08 83664-2552 | O19: REST./PIZZARIA/CHURR | P19: 0 | R19: 6 | S19: 36 | V19: 0 | W19: 0 | X19: 0 | Y19: 0 | Z19: 0 | AA19: 0 | AB19: 0 | AC19: 0 | AD19: Nao | AE19: Nao | AF19: 45518 | AG19: 46011 | AH19: 2031.11 | AI19: 3101.78 | AJ19: 14217.79 | AK19: 0 | AL19: 0 | AM19: 0 | AQ19: N | AS19: Fisica | AT19: Ativo | AU19: 501 | AV19: 10 | AW19: 1 | AX19: 45856 | AY19: SEX/ | AZ19: 46024 | BA19: 0 | BB19: 0 | BC19: 0 | BD19: 700 | BE19: 70 | BF19: 9 | BG19: 45536 | BH19: DOM/ | BI19: 46026 | BJ19: 0 | BK19: 0 | BL19: 0 | BM19: 0 | BN19: 0 | BO19: 0 | BP19: 3268.16 | BQ19: 3268.16 | BR19: 0 | BS19: 0 | BT19: 0 | BU19: 0 | BV19: 5573.6 | BW19: 5573.6 | BX19: 0 | BY19: 0 | BZ19: 0 | CA19: 0 | CB19: 4175.82 | CC19: Rota
A20: 345 | B20: 2 | C20: 58 | D20: 048.702.003-09 | F20: DEP DE AGUAS JONAS | G20: FRANCISCO JONAS DE FREITAS | H20: R TRIANGULO DO MARCO 11 | J20: ALEMAES | K20: MARCO | L20: CE | M20: 62.560-000 | N20: 88 89731-3007 | O20: DEPOSITO DE BEBIDAS | P20: 0 | R20: 3 | S20: 85 | V20: 1294 | W20: 0 | X20: 1294 | Y20: 7 | Z20: 0 | AA20: 5 | AB20: 0 | AC20: 0 | AD20: Nao | AE20: Nao | AF20: 45518 | AG20: 46004 | AH20: 855.3 | AI20: 1680.9 | AJ20: 5131.84 | AK20: 0 | AL20: 0 | AM20: 0 | AQ20: N | AS20: Fisica | AT20: Ativo | AU20: 102 | AV20: 10 | AW20: 1 | AX20: 45926 | AY20: SEX/ | AZ20: 46024 | BA20: 0 | BB20: 0 | BC20: 0 | BD20: 999 | BE20: 99 | BF20: 9 | BJ20: 0 | BK20: 0 | BL20: 0 | BM20: 3 | BN20: 1.13 | BO20: 695.44 | BP20: 1146 | BQ20: 1841.44 | BR20: 695.44 | BS20: 5 | BT20: 2.52 | BU20: 848.4 | BV20: 832.5 | BW20: 1680.9 | BX20: 0 | BY20: 0 | BZ20: 0 | CA20: 0 | CB20: 1307.31 | CC20: SUB
A21: 345 | B21: 2 | C21: 59 | D21: 155.742.613-91 | F21: MERC MARJO | G21: FRANCISCO DE ASSIS DO NASCIMENTO | H21: R GOV RAUL BARBOSA SN | J21: CENTRO | K21: MARCO | L21: CE | M21: 62.560-000 | N21: 08 89752-2153 | O21: ARMAZEM/MERCEARIA | P21: 0 | R21: 6 | S21: 42 | V21: 0 | W21: 0 | X21: 0 | Y21: 0 | Z21: 0 | AA21: 0 | AB21: 0 | AC21: 0 | AD21: Nao | AE21: Nao | AF21: 45518 | AG21: 46017 | AH21: 146.92 | AI21: 194.94 | AJ21: 1175.38 | AK21: 0 | AL21: 0 | AM21: 0 | AQ21: N | AS21: Fisica | AT21: Ativo | AU21: 102 | AV21: 10 | AW21: 1 | AX21: 45847 | AY21: QUA/ | AZ21: 46022 | BA21: 0 | BB21: 0 | BC21: 0 | BD21: 700 | BE21: 70 | BF21: 9 | BG21: 45536 | BH21: DOM/ | BI21: 46026 | BJ21: 0 | BK21: 0 | BL21: 0 | BM21: 0 | BN21: 0 | BO21: 0 | BP21: 295.22 | BQ21: 295.22 | BR21: 0 | BS21: 0 | BT21: 0 | BU21: 0 | BV21: 355.8 | BW21: 355.8 | BX21: 0 | BY21: 0 | BZ21: 0 | CA21: 0 | CB21: 365.12 | CC21: TRAD
A22: 345 | B22: 2 | C22: 66 | D22: 069.418.613-98 | F22: MERC ISAIAS TRIANGU | G22: FRANCISCO ALEXSANDRO RIBEIRO | H22: VIL TRIANGULO DO MARCO 10 | J22: TRIANGULO DO MARCO | K22: MARCO | L22: CE | M22: 62.560-000 | N22: 08 89625-6704 | O22: ARMAZEM/MERCEARIA | P22: 0 | R22: 6 | S22: 39 | V22: 0 | W22: 0 | X22: 0 | Y22: 0 | Z22: 0 | AA22: 0 | AB22: 0 | AC22: 0 | AD22: Nao | AE22: Nao | AF22: 45518 | AG22: 46020 | AH22: 358.99 | AI22: 832.79 | AJ22: 1794.98 | AK22: 0 | AL22: 0 | AM22: 0 | AQ22: N | AS22: Fisica | AT22: Ativo | AU22: 102 | AV22: 10 | AW22: 1 | AX22: 45842 | AY22: SEX/ | AZ22: 46024 | BA22: 0 | BB22: 0 | BC22: 0 | BD22: 700 | BE22: 70 | BF22: 9 | BG22: 45536 | BH22: DOM/ | BI22: 46026 | BJ22: 0 | BK22: 0 | BL22: 0 | BM22: 0 | BN22: 0 | BO22: 0 | BP22: 455.15 | BQ22: 455.15 | BR22: 0 | BS22: 0 | BT22: 0 | BU22: 0 | BV22: 1076.61 | BW22: 1076.61 | BX22: 0 | BY22: 0 | BZ22: 0 | CA22: 0 | CB22: 296.4 | CC22: TRAD
A23: 345 | B23: 2 | C23: 68 | D23: 709.361.883-91 | F23: DEP FURTUOSO SANTA | G23: JOSE FURTUOSO DE FREITAS | H23: VIL SANTA ROSA 10 | J23: SANTA ROSA | K23: MARCO | L23: CE | M23: 62.560-000 | N23: 08 89922-5756 | O23: DEPOSITO DE BEBIDAS | P23: 0 | R23: 6 | S23: 41 | V23: 0 | W23: 0 | X23: 0 | Y23: 0 | Z23: 0 | AA23: 0 | AB23: 0 | AC23: 0 | AD23: Nao | AE23: Nao | AF23: 45518 | AG23: 46014 | AH23: 2203.32 | AI23: 5484 | AJ23: 24236.6 | AK23: 0 | AL23: 0 | AM23: 0 | AQ23: N | AS23: Fisica | AT23: Ativo | AU23: 102 | AV23: 10 | AW23: 1 | AX23: 45537 | AY23: SEG/ | AZ23: 46027 | BA23: 0 | BB23: 0 | BC23: 0 | BD23: 700 | BE23: 70 | BF23: 9 | BG23: 45536 | BH23: DOM/ | BI23: 46026 | BJ23: 0 | BK23: 0 | BL23: 0 | BM23: 0 | BN23: 0 | BO23: 0 | BP23: 6798.38 | BQ23: 6798.38 | BR23: 0 | BS23: 0 | BT23: 0 | BU23: 0 | BV23: 12381.07 | BW23: 12381.07 | BX23: 0 | BY23: 0 | BZ23: 0 | CA23: 0 | CB23: 6739.19 | CC23: SUB
A24: 345 | B24: 2 | C24: 69 | D24: 025.215.253-08 | F24: DEPOSITO TIAGO MARC | G24: MANOEL TIAGO LEITAO | H24: RUA MANOEL RODRIGUES 10 | J24: CENTRO | K24: MARCO | L24: CE | M24: 62.560-000 | N24: 08 89863-5800 | O24: DEPOSITO DE BEBIDAS | P24: 0 | R24: 6 | S24: 42 | V24: 0 | W24: 0 | X24: 0 | Y24: 0 | Z24: 0 | AA24: 0 | AB24: 0 | AC24: 0 | AD24: Nao | AE24: Nao | AF24: 45518 | AG24: 46020 | AH24: 1103 | AI24: 3559.93 | AJ24: 15442.07 | AK24: 0 | AL24: 0 | AM24: 0 | AQ24: N | AS24: Fisica | AT24: Ativo | AU24: 102 | AV24: 10 | AW24: 1 | AX24: 45810 | AY24: SEG/ | AZ24: 46027 | BA24: 0 | BB24: 0 | BC24: 0 | BD24: 700 | BE24: 70 | BF24: 9 | BG24: 45536 | BH24: DOM/ | BI24: 46026 | BJ24: 0 | BK24: 0 | BL24: 0 | BM24: 0 | BN24: 0 | BO24: 0 | BP24: 6278.64 | BQ24: 6278.64 | BR24: 0 | BS24: 0 | BT24: 0 | BU24: 0 | BV24: 4965.45 | BW24: 4965.45 | BX24: 0 | BY24: 0 | BZ24: 0 | CA24: 0 | CB24: 6303.61 | CC24: SUB
A25: 345 | B25: 2 | C25: 71 | D25: 038.646.553-31 | F25: DEP E ARMAZEM RD MA | G25: LEIDYANA CRISTINA SILVA SILVEIRA | H25: RUA 30 DE JULHO 207 | J25: CENTRO | K25: MARCO | L25: CE | M25: 62.560-000 | N25: 08 89685-2389 | O25: DEPOSITO DE BEBIDAS | P25: 0 | R25: 6 | S25: 42 | V25: 0 | W25: 0 | X25: 0 | Y25: 0 | Z25: 0 | AA25: 0 | AB25: 0 | AC25: 0 | AD25: Nao | AE25: Nao | AF25: 45518 | AG25: 46020 | AH25: 3692.35 | AI25: 12661.16 | AJ25: 44308.26 | AK25: 0 | AL25: 0 | AM25: 0 | AQ25: N | AS25: Fisica | AT25: Ativo | AU25: 501 | AV25: 10 | AW25: 1 | AX25: 45856 | AY25: SEX/ | AZ25: 46024 | BA25: 0 | BB25: 0 | BC25: 0 | BD25: 700 | BE25: 70 | BF25: 9 | BG25: 45536 | BH25: DOM/ | BI25: 46026 | BJ25: 0 | BK25: 0 | BL25: 0 | BM25: 0 | BN25: 0 | BO25: 0 | BP25: 21820.45 | BQ25: 21820.45 | BR25: 0 | BS25: 0 | BT25: 0 | BU25: 0 | BV25: 20553.61 | BW25: 20553.61 | BX25: 0 | BY25: 0 | BZ25: 0 | CA25: 0 | CB25: 20907.99 | CC25: SUB
A26: 345 | B26: 2 | C26: 75 | D26: 080.143.583-84 | F26: LANCHONET MAIS SABOR | G26: FRANCISCO JOEL DE FREITAS | H26: AV GUIDO OSTERNO 10 | J26: CENTRO | K26: MARCO | L26: CE | M26: 62.560-000 | N26: 88 89816-9737 | O26: LANCHONETE/PASTELARI | P26: 0 | R26: 3 | S26: 85 | V26: 1000 | W26: 0 | X26: 1000 | Y26: 7 | Z26: 0 | AA26: 0 | AB26: 0 | AC26: 0 | AD26: Nao | AE26: Nao | AF26: 45518 | AG26: 46009 | AH26: 302.65 | AI26: 711.6 | AJ26: 2421.25 | AK26: 0 | AL26: 0 | AM26: 0 | AQ26: N | AS26: Fisica | AT26: Ativo | AU26: 102 | AV26: 10 | AW26: 1 | AX26: 45847 | AY26: QUA/ | AZ26: 46022 | BA26: 0 | BB26: 0 | BC26: 0 | BD26: 700 | BE26: 70 | BF26: 9 | BG26: 45536 | BH26: DOM/ | BI26: 46026 | BJ26: 0 | BK26: 0 | BL26: 0 | BM26: 0 | BN26: 0 | BO26: 0 | BP26: 177.9 | BQ26: 830.2 | BR26: 0 | BS26: 0 | BT26: 0 | BU26: 0 | BV26: 1005.59 | BW26: 1005.59 | BX26: 0 | BY26: 0 | BZ26: 0 | CA26: 0 | CB26: 642.25 | CC26: Rota
A27: 345 | B27: 2 | C27: 78 | D27: 34.437.443/0001-66 | F27: BAR MANUEL MARCO | G27: MANOEL EDSON SILVA | H27: R RIOS SN | J27: CENTRO | K27: MARCO | L27: CE | M27: 62.560-000 | N27: 08 89809-2367 | O27: BAR/BARZINHO | P27: 0 | R27: 6 | S27: 42 | V27: 0 | W27: 0 | X27: 0 | Y27: 0 | Z27: 0 | AA27: 0 | AB27: 0 | AC27: 0 | AD27: Nao | AE27: Nao | AF27: 45518 | AG27: 46017 | AH27: 1052.8 | AI27: 1719 | AJ27: 12633.66 | AK27: 0 | AL27: 0 | AM27: 0 | AQ27: N | AS27: Juridica | AT27: Ativo | AU27: 102 | AV27: 10 | AW27: 1 | AX27: 45847 | AY27: QUA/ | AZ27: 46022 | BA27: 0 | BB27: 0 | BC27: 0 | BD27: 700 | BE27: 70 | BF27: 9 | BG27: 45536 | BH27: DOM/ | BI27: 46026 | BJ27: 0 | BK27: 0 | BL27: 0 | BM27: 0 | BN27: 0 | BO27: 0 | BP27: 3352.15 | BQ27: 3352.15 | BR27: 0 | BS27: 0 | BT27: 0 | BU27: 0 | BV27: 4129.68 | BW27: 4129.68 | BX27: 0 | BY27: 0 | BZ27: 0 | CA27: 0 | CB27: 5083.39 | CC27: Rota
A28: 345 | B28: 2 | C28: 79 | D28: 633.695.833-72 | F28: DEP DO JUNIOR MARCO | G28: ANTONIO FLAVIO DOS SANTOS | H28: RUA 22 DE NOVEMBRO 10 | J28: CENTRO | K28: MARCO | L28: CE | M28: 62.560-000 | N28: 08 89702-1221 | O28: DEPOSITO DE BEBIDAS | P28: 0 | R28: 6 | S28: 42 | V28: 0 | W28: 0 | X28: 0 | Y28: 0 | Z28: 0 | AA28: 0 | AB28: 0 | AC28: 0 | AD28: Nao | AE28: Nao | AF28: 45518 | AG28: 46014 | AH28: 5239.62 | AI28: 13046.41 | AJ28: 68115.12 | AK28: 0 | AL28: 0 | AM28: 0 | AQ28: N | AS28: Fisica | AT28: Ativo | AU28: 501 | AV28: 10 | AW28: 1 | AX28: 45856 | AY28: SEX/ | AZ28: 46024 | BA28: 0 | BB28: 0 | BC28: 0 | BD28: 700 | BE28: 70 | BF28: 9 | BG28: 45536 | BH28: DOM/ | BI28: 46026 | BJ28: 0 | BK28: 0 | BL28: 0 | BM28: 0 | BN28: 0 | BO28: 0 | BP28: 31077.22 | BQ28: 31077.22 | BR28: 0 | BS28: 0 | BT28: 0 | BU28: 0 | BV28: 22275.7 | BW28: 22275.7 | BX28: 0 | BY28: 0 | BZ28: 0 | CA28: 0 | CB28: 21111.22 | CC28: SUB
A29: 345 | B29: 2 | C29: 80 | D29: 010.374.023-67 | F29: CONV POSTO ROCHA | G29: ANDRE GUSTAVO OLIVEIRA ROCHA | H29: RUA BOM JESUS 10 | J29: TRIANGULO DO MARCO | K29: MARCO | L29: CE | M29: 62.560-000 | N29: 08 59970-6842 | O29: LOJA DE CONVENIENCIA | P29: 0 | R29: 6 | S29: 40 | V29: 0 | W29: 0 | X29: 0 | Y29: 0 | Z29: 0 | AA29: 0 | AB29: 0 | AC29: 0 | AD29: Nao | AE29: Nao | AF29: 45518 | AG29: 46017 | AH29: 695.48 | AI29: 881.68 | AJ29: 8345.84 | AK29: 0 | AL29: 0 | AM29: 0 | AQ29: N | AS29: Fisica | AT29: Ativo | AU29: 102 | AV29: 10 | AW29: 1 | AX29: 45903 | AY29: QUA/ | AZ29: 46022 | BA29: 0 | BB29: 0 | BC29: 0 | BD29: 700 | BE29: 70 | BF29: 9 | BG29: 45536 | BH29: DOM/ | BI29: 46026 | BJ29: 0 | BK29: 0 | BL29: 0 | BM29: 0 | BN29: 0 | BO29: 0 | BP29: 2508.34 | BQ29: 2508.34 | BR29: 0 | BS29: 0 | BT29: 0 | BU29: 0 | BV29: 2979.02 | BW29: 2979.02 | BX29: 0 | BY29: 0 | BZ29: 0 | CA29: 0 | CB29: 2248.15 | CC29: Lj. Conveniencia
A30: 345 | B30: 2 | C30: 81 | D30: 011.272.653-42 | F30: DEP DO MARCELO MARC | G30: MARCELO SILVA MOURA | H30: RUA MANOEL CLOVES RIOS 804 | J30: ALEMAES | K30: MARCO | L30: CE | M30: 62.560-000 | N30: 08 89724-0449 | O30: DEPOSITO DE BEBIDAS | P30: 0 | R30: 6 | S30: 41 | V30: 0 | W30: 0 | X30: 0 | Y30: 0 | Z30: 0 | AA30: 0 | AB30: 0 | AC30: 0 | AD30: Nao | AE30: Nao | AF30: 45518 | AG30: 46013 | AH30: 1642.81 | AI30: 1991.2 | AJ30: 4928.43 | AK30: 0 | AL30: 0 | AM30: 0 | AQ30: N | AS30: Fisica | AT30: Ativo | AU30: 102 | AV30: 10 | AW30: 1 | AX30: 45850 | AY30: SAB/ | AZ30: 46025 | BA30: 0 | BB30: 0 | BC30: 0 | BD30: 700 | BE30: 70 | BF30: 9 | BG30: 45536 | BH30: DOM/ | BI30: 46026 | BJ30: 0 | BK30: 0 | BL30: 0 | BM30: 0 | BN30: 0 | BO30: 0 | BP30: 0 | BQ30: 0 | BR30: 0 | BS30: 0 | BT30: 0 | BU30: 0 | BV30: 4928.43 | BW30: 4928.43 | BX30: 0 | BY30: 0 | BZ30: 0 | CA30: 0 | CB30: 0 | CC30: SUB
A31: 345 | B31: 2 | C31: 82 | D31: 069.895.533-16 | F31: MERC JP | G31: MARIA KAINARA VASCONCELOS | H31: R TRIANGULO DO MARCO 10 | J31: TRIANGULO DO MARCO | K31: MARCO | L31: CE | M31: 62.560-000 | N31: 88 89909-2507 | O31: ARMAZEM/MERCEARIA | P31: 0 | R31: 3 | S31: 89 | V31: 4328 | W31: 0 | X31: 4328 | Y31: 0 | Z31: 0 | AA31: 0 | AB31: 0 | AC31: 0 | AD31: Nao | AE31: Nao | AF31: 45518 | AG31: 46018 | AH31: 2020.53 | AI31: 4186.29 | AJ31: 18184.85 | AK31: 0 | AL31: 0 | AM31: 0 | AQ31: N | AS31: Fisica | AT31: Ativo | AU31: 102 | AV31: 10 | AW31: 1 | AX31: 45995 | AY31: QUI/ | AZ31: 46023 | BA31: 0 | BB31: 0 | BC31: 0 | BD31: 700 | BE31: 70 | BF31: 9 | BG31: 45536 | BH31: DOM/ | BI31: 46026 | BJ31: 0 | BK31: 0 | BL31: 0 | BM31: 0 | BN31: 0 | BO31: 0 | BP31: 10316.65 | BQ31: 10316.65 | BR31: 0 | BS31: 0 | BT31: 0 | BU31: 0 | BV31: 6939.2 | BW31: 6939.2 | BX31: 0 | BY31: 0 | BZ31: 0 | CA31: 0 | CB31: 7870.2 | CC31: TRAD
A32: 345 | B32: 2 | C32: 83 | D32: 725.858.113-87 | F32: BAIAO DE DOIS | G32: FRANCISCO EDSON MENEZES | H32: R RUA GOVERNADOR CESAR CALS SN | J32: CENTRO | K32: MARCO | L32: CE | M32: 62.560-000 | N32: 88 99914-3539 | O32: REST./PIZZARIA/CHURR | P32: 0 | R32: 3 | S32: 83 | V32: 1000 | W32: 952.99 | X32: 47.01 | Y32: 0 | Z32: 0 | AA32: 9 | AB32: 3 | AC32: 0 | AD32: Nao | AE32: Nao | AF32: 45518 | AG32: 46018 | AH32: 317.62 | AI32: 762.46 | AJ32: 1588.12 | AK32: 762.46 | AL32: 190.53 | AM32: 0 | AQ32: N | AS32: Fisica | AT32: Ativo | AU32: 102 | AV32: 10 | AW32: 1 | AX32: 45973 | AY32: QUA/ | AZ32: 46022 | BA32: 0 | BB32: 0 | BC32: 0 | BD32: 999 | BE32: 99 | BF32: 9 | BJ32: 0 | BK32: 0 | BL32: 0 | BM32: 0 | BN32: 0 | BO32: 0 | BP32: 418.15 | BQ32: 418.15 | BR32: 0 | BS32: 7.61 | BT32: 7.61 | BU32: 1169.97 | BV32: 0 | BW32: 1169.97 | BX32: 190.53 | BY32: 16.29 | BZ32: 0 | CA32: 0 | CB32: 139.38 | CC32: Rota
A33: 345 | B33: 2 | C33: 89 | D33: 070.759.943-10 | F33: MERC SAO GERALDO LA | G33: CANDIDA EDUARDA FREITAS DA SILVA | H33: R PV LAGOA DE SANTA ROSA 10 | J33: LAGOA DE SANTA ROSA | K33: MARCO | L33: CE | M33: 62.560-000 | N33: 88 89746-5132 | O33: ARMAZEM/MERCEARIA | P33: 0 | R33: 3 | S33: 89 | V33: 0 | W33: 0 | X33: 0 | Y33: 0 | Z33: 0 | AA33: 0 | AB33: 0 | AC33: 0 | AD33: Nao | AE33: Nao | AF33: 45518 | AG33: 46018 | AH33: 1403.85 | AI33: 2005.5 | AJ33: 2807.7 | AK33: 0 | AL33: 0 | AM33: 0 | AQ33: N | AS33: Fisica | AT33: Ativo | AU33: 102 | AV33: 10 | AW33: 1 | AX33: 45995 | AY33: QUI/ | AZ33: 46023 | BA33: 0 | BB33: 0 | BC33: 0 | BD33: 700 | BE33: 70 | BF33: 9 | BG33: 45536 | BH33: DOM/ | BI33: 46026 | BJ33: 0 | BK33: 0 | BL33: 0 | BM33: 0 | BN33: 0 | BO33: 0 | BP33: 0 | BQ33: 0 | BR33: 0 | BS33: 0 | BT33: 0 | BU33: 0 | BV33: 2807.7 | BW33: 2807.7 | BX33: 0 | BY33: 0 | BZ33: 0 | CA33: 0 | CB33: 0 | CC33: TRAD
A34: 345 | B34: 2 | C34: 96 | D34: 616.145.133-68 | F34: DEP SAO ROQUE MARCO | G34: ALEX DOS SANTOS | H34: R GOV CESAR CARLS SN | J34: CENTRO | K34: MARCO | L34: CE | M34: 62.560-000 | N34: 08 89840-2108 | O34: DEPOSITO DE BEBIDAS | P34: 0 | R34: 6 | S34: 40 | V34: 0 | W34: 0 | X34: 0 | Y34: 0 | Z34: 0 | AA34: 0 | AB34: 0 | AC34: 0 | AD34: Nao | AE34: Nao | AF34: 45518 | AG34: 46014 | AH34: 909.74 | AI34: 2290.4 | AJ34: 5458.45 | AK34: 0 | AL34: 0 | AM34: 0 | AQ34: N | AS34: Fisica | AT34: Ativo | AU34: 102 | AV34: 10 | AW34: 1 | AX34: 45810 | AY34: SEG/ | AZ34: 46027 | BA34: 0 | BB34: 0 | BC34: 0 | BD34: 700 | BE34: 70 | BF34: 9 | BG34: 45536 | BH34: DOM/ | BI34: 46026 | BJ34: 0 | BK34: 0 | BL34: 0 | BM34: 0 | BN34: 0 | BO34: 0 | BP34: 1982.05 | BQ34: 1982.05 | BR34: 0 | BS34: 0 | BT34: 0 | BU34: 0 | BV34: 2883.4 | BW34: 2883.4 | BX34: 0 | BY34: 0 | BZ34: 0 | CA34: 0 | CB34: 1431.35 | CC34: SUB
A35: 345 | B35: 2 | C35: 97 | D35: 014.531.423-55 | F35: DEPOSITO O PINTO | G35: PAULO ALEX DA COSTA DUARTE | H35: R PADRE APOLIANO SN | J35: CENTRO | K35: MARCO | L35: CE | M35: 62.560-000 | N35: 88 89652-1818 | O35: REST./PIZZARIA/CHURR | P35: 0 | R35: 3 | S35: 85 | V35: 2262 | W35: 0 | X35: 2262 | Y35: 0 | Z35: 0 | AA35: 0 | AB35: 0 | AC35: 0 | AD35: Nao | AE35: Nao | AF35: 45518 | AG35: 46021 | AH35: 2008.85 | AI35: 4834.96 | AJ35: 16070.83 | AK35: 0 | AL35: 0 | AM35: 0 | AQ35: N | AS35: Fisica | AT35: Ativo | AU35: 102 | AV35: 10 | AW35: 1 | AX35: 45810 | AY35: SEG/ | AZ35: 46027 | BA35: 0 | BB35: 0 | BC35: 0 | BD35: 700 | BE35: 70 | BF35: 9 | BG35: 45536 | BH35: DOM/ | BI35: 46026 | BJ35: 0 | BK35: 0 | BL35: 0 | BM35: 0 | BN35: 0 | BO35: 0 | BP35: 2511.91 | BQ35: 2511.91 | BR35: 0 | BS35: 0 | BT35: 0 | BU35: 0 | BV35: 9252.63 | BW35: 9252.63 | BX35: 0 | BY35: 0 | BZ35: 0 | CA35: 0 | CB35: 3655.87 | CC35: SUB
A36: 345 | B36: 2 | C36: 102 | D36: 064.497.153-32 | F36: MERC VVN LAGOA DO C | G36: JOAO PAULO DE PAULO SOUSA | H36: R PV LAGOA DO CANEMA SN | I36: PROX AO MERCADINHO VVN | J36: LAGOA DO CANEMA | K36: ACARAU | L36: CE | M36: 62.580-000 | N36: 08 89695-7642 | O36: ARMAZEM/MERCEARIA | P36: 0 | R36: 6 | S36: 39 | V36: 0 | W36: 0 | X36: 0 | Y36: 0 | Z36: 0 | AA36: 0 | AB36: 0 | AC36: 0 | AD36: Nao | AE36: Nao | AF36: 45518 | AG36: 46004 | AH36: 249.48 | AI36: 296 | AJ36: 1247.4 | AK36: 0 | AL36: 0 | AM36: 0 | AQ36: N | AS36: Fisica | AT36: Ativo | AU36: 101 | AV36: 10 | AW36: 1 | AX36: 45534 | AY36: SEX/ | AZ36: 46024 | BA36: 0 | BB36: 0 | BC36: 0 | BD36: 700 | BE36: 70 | BF36: 9 | BG36: 45536 | BH36: DOM/ | BI36: 46026 | BJ36: 0 | BK36: 0 | BL36: 0 | BM36: 0 | BN36: 0 | BO36: 0 | BP36: 532.8 | BQ36: 532.8 | BR36: 0 | BS36: 0 | BT36: 0 | BU36: 0 | BV36: 236.8 | BW36: 236.8 | BX36: 0 | BY36: 0 | BZ36: 0 | CA36: 0 | CB36: 492.2 | CC36: AS 1-4
A37: 345 | B37: 2 | C37: 103 | D37: 38.251.332/0001-11 | F37: MERC SAO FRANCISCO | G37: F KEILO ALVES ME | H37: RUA BOSQUE DOS NAMORADOS 425 | J37: TRIANGULO DO MARCO | K37: MARCO | L37: CE | M37: 62.560-000 | N37: 08 89819-9470 | O37: ARMAZEM/MERCEARIA | P37: 0 | R37: 6 | S37: 44 | V37: 0 | W37: 0 | X37: 0 | Y37: 0 | Z37: 0 | AA37: 0 | AB37: 0 | AC37: 0 | AD37: Nao | AE37: Nao | AF37: 45518 | AG37: 46020 | AH37: 1556.84 | AI37: 3848.02 | AJ37: 17125.24 | AK37: 0 | AL37: 0 | AM37: 0 | AQ37: N | AS37: Juridica | AT37: Ativo | AU37: 501 | AV37: 10 | AW37: 1 | AX37: 45856 | AY37: SEX/ | AZ37: 46024 | BA37: 0 | BB37: 0 | BC37: 0 | BD37: 700 | BE37: 70 | BF37: 9 | BG37: 45536 | BH37: DOM/ | BI37: 46026 | BJ37: 0 | BK37: 0 | BL37: 0 | BM37: 0 | BN37: 0 | BO37: 0 | BP37: 5707.18 | BQ37: 5707.18 | BR37: 0 | BS37: 0 | BT37: 0 | BU37: 0 | BV37: 9383.44 | BW37: 9383.44 | BX37: 0 | BY37: 0 | BZ37: 0 | CA37: 0 | CB37: 3719.51 | CC37: TRAD
A38: 345 | B38: 2 | C38: 105 | D38: 268.408.038-05 | F38: LANCHONETE CHAPADAO | G38: CLEBER JOSE DE SOUZA | H38: R JOSE MARIA FARIAS SN | J38: ALEMAES | K38: MARCO | L38: CE | M38: 62.560-000 | N38: 08 89950-5408 | O38: LANCHONETE/PASTELARI | P38: 0 | R38: 6 | S38: 36 | V38: 0 | W38: 0 | X38: 0 | Y38: 0 | Z38: 0 | AA38: 0 | AB38: 0 | AC38: 0 | AD38: Nao | AE38: Nao | AF38: 45518 | AG38: 46009 | AH38: 710.38 | AI38: 1300 | AJ38: 4262.28 | AK38: 0 | AL38: 0 | AM38: 0 | AQ38: N | AS38: Fisica | AT38: Ativo | AU38: 102 | AV38: 10 | AW38: 1 | AX38: 45847 | AY38: QUA/ | AZ38: 46022 | BA38: 0 | BB38: 0 | BC38: 0 | BD38: 700 | BE38: 70 | BF38: 9 | BG38: 45536 | BH38: DOM/ | BI38: 46026 | BJ38: 0 | BK38: 0 | BL38: 0 | BM38: 0 | BN38: 0 | BO38: 0 | BP38: 1300 | BQ38: 1300 | BR38: 0 | BS38: 0 | BT38: 0 | BU38: 0 | BV38: 1318.48 | BW38: 1318.48 | BX38: 0 | BY38: 0 | BZ38: 0 | CA38: 0 | CB38: 1357.22 | CC38: Rota
A39: 345 | B39: 2 | C39: 108 | D39: 027.844.783-00 | F39: DEP WLR RACOES MARC | G39: JOSE CARVALHO ROCHA | H39: RUA PROJETADA 3 | J39: ALEMAES | K39: MARCO | L39: CE | M39: 62.560-000 | N39: 08 89694-7763 | O39: DEPOSITO DE BEBIDAS | P39: 0 | R39: 6 | S39: 42 | V39: 0 | W39: 0 | X39: 0 | Y39: 0 | Z39: 0 | AA39: 0 | AB39: 0 | AC39: 0 | AD39: Nao | AE39: Nao | AF39: 45518 | AG39: 46019 | AH39: 5590 | AI39: 11370.15 | AJ39: 89440.06 | AK39: 0 | AL39: 0 | AM39: 0 | AQ39: N | AS39: Fisica | AT39: Ativo | AU39: 501 | AV39: 10 | AW39: 1 | AX39: 45856 | AY39: SEX/ | AZ39: 46024 | BA39: 0 | BB39: 0 | BC39: 0 | BD39: 700 | BE39: 70 | BF39: 9 | BG39: 45536 | BH39: DOM/ | BI39: 46026 | BJ39: 0 | BK39: 0 | BL39: 0 | BM39: 0 | BN39: 0 | BO39: 0 | BP39: 31297.62 | BQ39: 31297.62 | BR39: 0 | BS39: 0 | BT39: 0 | BU39: 0 | BV39: 36835.74 | BW39: 36835.74 | BX39: 0 | BY39: 0 | BZ39: 0 | CA39: 0 | CB39: 25719.79 | CC39: SUB
A40: 345 | B40: 2 | C40: 109 | D40: 083.532.053-78 | F40: MERC DO JOELIO TRIA | G40: JOSE JOELIO MARINHO | H40: R DO POSTO ROCHA SN | J40: TRIANGULO DO MARCO | K40: MARCO | L40: CE | M40: 62.560-000 | N40: 08 88898-7889 | O40: ARMAZEM/MERCEARIA | P40: 0 | R40: 6 | S40: 42 | V40: 0 | W40: 0 | X40: 0 | Y40: 0 | Z40: 0 | AA40: 0 | AB40: 0 | AC40: 0 | AD40: Nao | AE40: Nao | AF40: 45518 | AG40: 46017 | AH40: 2626.08 | AI40: 3743.6 | AJ40: 34139.16 | AK40: 0 | AL40: 0 | AM40: 0 | AQ40: N | AS40: Fisica | AT40: Ativo | AU40: 102 | AV40: 10 | AW40: 1 | AX40: 45842 | AY40: SEX/ | AZ40: 46024 | BA40: 0 | BB40: 0 | BC40: 0 | BD40: 700 | BE40: 70 | BF40: 9 | BG40: 45536 | BH40: DOM/ | BI40: 46026 | BJ40: 0 | BK40: 0 | BL40: 0 | BM40: 0 | BN40: 0 | BO40: 0 | BP40: 14360 | BQ40: 14360 | BR40: 0 | BS40: 0 | BT40: 0 | BU40: 0 | BV40: 10593.72 | BW40: 10593.72 | BX40: 0 | BY40: 0 | BZ40: 0 | CA40: 0 | CB40: 9844.12 | CC40: TRAD
A41: 345 | B41: 2 | C41: 117 | D41: 906.919.033-87 | F41: MERC VASCONCELOS | G41: JOSE REGINALDO VASCONCELOS | H41: RUA RUA GOVERNADOR RAUL BARBOSA 1054 | J41: COQUEIRINHO | K41: MARCO | L41: CE | M41: 62.560-000 | N41: 08 89857-9070 | O41: ARMAZEM/MERCEARIA | P41: 0 | R41: 6 | S41: 41 | V41: 0 | W41: 0 | X41: 0 | Y41: 0 | Z41: 0 | AA41: 0 | AB41: 0 | AC41: 0 | AD41: Nao | AE41: Nao | AF41: 45518 | AG41: 46011 | AH41: 120.8 | AI41: 186 | AJ41: 483.21 | AK41: 0 | AL41: 0 | AM41: 0 | AQ41: N | AS41: Fisica | AT41: Ativo | AU41: 102 | AV41: 10 | AW41: 1 | AX41: 45848 | AY41: QUI/ | AZ41: 46023 | BA41: 0 | BB41: 0 | BC41: 0 | BD41: 700 | BE41: 70 | BF41: 9 | BG41: 45536 | BH41: DOM/ | BI41: 46026 | BJ41: 0 | BK41: 0 | BL41: 0 | BM41: 0 | BN41: 0 | BO41: 0 | BP41: 111.21 | BQ41: 111.21 | BR41: 0 | BS41: 0 | BT41: 0 | BU41: 0 | BV41: 186 | BW41: 186 | BX41: 0 | BY41: 0 | BZ41: 0 | CA41: 0 | CB41: 122.6 | CC41: TRAD
A42: 345 | B42: 2 | C42: 118 | D42: 070.572.763-70 | F42: MERC SAO MANOEL NETO | G42: MARIANA ANTONIA MARAIS FONTELES | H42: AVE PREF GUIDO OSTERNO 10 | J42: CENTRO | K42: MARCO | L42: CE | M42: 62.560-000 | N42: 08 89984-8688 | O42: ARMAZEM/MERCEARIA | P42: 0 | R42: 6 | S42: 41 | V42: 0 | W42: 0 | X42: 0 | Y42: 0 | Z42: 0 | AA42: 0 | AB42: 0 | AC42: 0 | AD42: Nao | AE42: Nao | AF42: 45518 | AG42: 46021 | AH42: 981.88 | AI42: 3512.09 | AJ42: 9818.81 | AK42: 0 | AL42: 0 | AM42: 0 | AQ42: N | AS42: Fisica | AT42: Ativo | AU42: 102 | AV42: 10 | AW42: 1 | AX42: 45847 | AY42: QUA/ | AZ42: 46022 | BA42: 0 | BB42: 0 | BC42: 0 | BD42: 700 | BE42: 70 | BF42: 9 | BG42: 45536 | BH42: DOM/ | BI42: 46026 | BJ42: 0 | BK42: 0 | BL42: 0 | BM42: 0 | BN42: 0 | BO42: 0 | BP42: 528.27 | BQ42: 528.27 | BR42: 0 | BS42: 0 | BT42: 0 | BU42: 0 | BV42: 1411.63 | BW42: 1411.63 | BX42: 0 | BY42: 0 | BZ42: 0 | CA42: 0 | CB42: 5090 | CC42: TRAD
A43: 345 | B43: 2 | C43: 124 | D43: 949.074.553-72 | F43: DEP DIOGO ACARAU | G43: DIOGO HENRIQUE CARNEIRO DE BARROS | H43: RUA AVENIDA NICODEMOS ARAUJO 874 | J43: PAULO VI | K43: ACARAU | L43: CE | M43: 62.580-000 | N43: 08 48147-0116 | O43: DEPOSITO DE BEBIDAS | P43: 0 | R43: 6 | S43: 40 | V43: 0 | W43: 0 | X43: 0 | Y43: 0 | Z43: 0 | AA43: 0 | AB43: 0 | AC43: 0 | AD43: Nao | AE43: Nao | AF43: 45518 | AG43: 46008 | AH43: 742.27 | AI43: 1366.4 | AJ43: 6680.48 | AK43: 0 | AL43: 0 | AM43: 0 | AQ43: N | AS43: Fisica | AT43: Ativo | AU43: 101 | AV43: 10 | AW43: 1 | AX43: 45874 | AY43: TER/ | AZ43: 46028 | BA43: 0 | BB43: 0 | BC43: 0 | BD43: 700 | BE43: 70 | BF43: 9 | BG43: 45536 | BH43: DOM/ | BI43: 46026 | BJ43: 0 | BK43: 0 | BL43: 0 | BM43: 0 | BN43: 0 | BO43: 0 | BP43: 2079.48 | BQ43: 2079.48 | BR43: 0 | BS43: 0 | BT43: 0 | BU43: 0 | BV43: 1954.9 | BW43: 1954.9 | BX43: 0 | BY43: 0 | BZ43: 0 | CA43: 0 | CB43: 2396.63 | CC43: SUB
A44: 345 | B44: 2 | C44: 132 | D44: 059.076.153-62 | F44: DEP O CHIQUINHO VIL | G44: EFIGENIA LOPES DA SILVA | H44: VL VILA GADO BRAVO SN | I44: SN | J44: VILA GADO BRAVO | K44: MARCO | L44: CE | M44: 62.560-000 | N44: 08 89845-8319 | O44: DEPOSITO DE BEBIDAS | P44: 0 | R44: 6 | S44: 40 | V44: 0 | W44: 0 | X44: 0 | Y44: 0 | Z44: 0 | AA44: 0 | AB44: 0 | AC44: 0 | AD44: Nao | AE44: Nao | AF44: 45518 | AG44: 46021 | AH44: 1900.78 | AI44: 2632.91 | AJ44: 5702.35 | AK44: 0 | AL44: 0 | AM44: 0 | AQ44: N | AS44: Fisica | AT44: Ativo | AU44: 102 | AV44: 10 | AW44: 1 | AX44: 45537 | AY44: SEG/ | AZ44: 46027 | BA44: 0 | BB44: 0 | BC44: 0 | BD44: 700 | BE44: 70 | BF44: 9 | BG44: 45536 | BH44: DOM/ | BI44: 46026 | BJ44: 0 | BK44: 0 | BL44: 0 | BM44: 0 | BN44: 0 | BO44: 0 | BP44: 2632.91 | BQ44: 2632.91 | BR44: 0 | BS44: 0 | BT44: 0 | BU44: 0 | BV44: 3069.44 | BW44: 3069.44 | BX44: 0 | BY44: 0 | BZ44: 0 | CA44: 0 | CB44: 1608.43 | CC44: SUB
A45: 345 | B45: 2 | C45: 135 | D45: 063.389.523-79 | F45: DEP DE BEBIDAS RIOS | G45: FELIPE RIOS SILVA | H45: R PADRE APOLIANO SN | J45: ALEMAES | K45: MARCO | L45: CE | M45: 62.560-000 | N45: 08 89605-3644 | O45: DEPOSITO DE BEBIDAS | P45: 0 | R45: 6 | S45: 41 | V45: 0 | W45: 0 | X45: 0 | Y45: 0 | Z45: 0 | AA45: 0 | AB45: 0 | AC45: 0 | AD45: Nao | AE45: Nao | AF45: 45518 | AG45: 46020 | AH45: 1467.61 | AI45: 4569.53 | AJ45: 17611.43 | AK45: 0 | AL45: 0 | AM45: 0 | AQ45: N | AS45: Fisica | AT45: Ativo | AU45: 501 | AV45: 10 | AW45: 1 | AX45: 45856 | AY45: SEX/ | AZ45: 46024 | BA45: 0 | BB45: 0 | BC45: 0 | BD45: 700 | BE45: 70 | BF45: 9 | BG45: 45536 | BH45: DOM/ | BI45: 46026 | BJ45: 0 | BK45: 0 | BL45: 0 | BM45: 0 | BN45: 0 | BO45: 0 | BP45: 5384.38 | BQ45: 5384.38 | BR45: 0 | BS45: 0 | BT45: 0 | BU45: 0 | BV45: 8108.08 | BW45: 8108.08 | BX45: 0 | BY45: 0 | BZ45: 0 | CA45: 0 | CB45: 5129.29 | CC45: SUB
...
